[2022-10-07 15:45:30,894:gps:ERROR:Failed to get serial COM-connection]
Traceback (most recent call last):
  File "C:\Users\Lukas\Documents\Docs\Coding\Python\Wlan Map\mainscript\gps.py", line 25, in get_gps
    return serial.Serial(f"com{com_port}", 4800)
  File "C:\Users\Lukas\Documents\Docs\Coding\Python\Wlan Map\env\lib\site-packages\serial\serialwin32.py", line 33, in __init__
    super(Serial, self).__init__(*args, **kwargs)
  File "C:\Users\Lukas\Documents\Docs\Coding\Python\Wlan Map\env\lib\site-packages\serial\serialutil.py", line 244, in __init__
    self.open()
  File "C:\Users\Lukas\Documents\Docs\Coding\Python\Wlan Map\env\lib\site-packages\serial\serialwin32.py", line 64, in open
    raise SerialException("could not open port {!r}: {!r}".format(self.portstr, ctypes.WinError()))
serial.serialutil.SerialException: could not open port 'com1': FileNotFoundError(2, 'Das System kann die angegebene Datei nicht finden.', None, 2)
